2024-12-05 15:57:53,434-DCInside.log-INFO-__init__.py:485-[10352] open: get <https://www.dcinside.com/> with <1200,800>
2024-12-05 16:30:09,089-DCInside.log-INFO-__init__.py:485-[10308] open: get <https://www.dcinside.com/> with <1200,800>
2024-12-05 16:32:07,048-DCInside.log-ERROR-__init__.py:475-[5384] open Error: list index out of range

2024-12-05 16:32:07,048-DCInside.log-ERROR-__init__.py:476-[5384] Traceback (most recent call last):
  File "C:\Users\argos\Desktop\data_extract\modules\dcinside\venv\lib\site-packages\alabslib\selenium\__init__.py", line 468, in __init__
    self.browser_version = self._get_browser_version()
  File "C:\Users\argos\Desktop\data_extract\modules\dcinside\venv\lib\site-packages\alabslib\selenium\__init__.py", line 142, in _get_browser_version
    bv = lines[-1].split()[0]
IndexError: list index out of range


2024-12-05 16:32:17,303-DCInside.log-INFO-__init__.py:485-[13996] open: get <https://www.dcinside.com/> with <1200,800>
2024-12-05 16:33:36,069-DCInside.log-INFO-__init__.py:499-[13996] closed
2024-12-05 16:33:46,631-DCInside.log-INFO-__init__.py:485-[1152] open: get <https://www.dcinside.com/> with <1200,800>
2024-12-05 16:35:30,155-DCInside.log-INFO-__init__.py:485-[6532] open: get <https://www.dcinside.com/> with <1200,800>
2024-12-05 16:35:57,738-DCInside.log-INFO-__init__.py:499-[6532] closed
2024-12-05 16:37:15,724-DCInside.log-INFO-__init__.py:485-[10320] open: get <https://www.dcinside.com/> with <1200,800>
2024-12-05 16:37:27,316-DCInside.log-INFO-__init__.py:499-[10320] closed
2024-12-05 16:43:04,729-DCInside.log-INFO-__init__.py:485-[11312] open: get <https://www.dcinside.com/> with <1200,800>
2024-12-05 16:43:15,831-DCInside.log-INFO-__init__.py:499-[11312] closed
2024-12-05 16:45:48,622-DCInside.log-INFO-__init__.py:485-[5676] open: get <https://www.dcinside.com/> with <1200,800>
2024-12-05 16:45:55,023-DCInside.log-INFO-__init__.py:499-[5676] closed
2024-12-05 16:46:49,364-DCInside.log-ERROR-__init__.py:475-[7104] open Error: list index out of range

2024-12-05 16:46:49,365-DCInside.log-ERROR-__init__.py:476-[7104] Traceback (most recent call last):
  File "C:\Users\argos\Desktop\data_extract\modules\dcinside\venv\lib\site-packages\alabslib\selenium\__init__.py", line 468, in __init__
    self.browser_version = self._get_browser_version()
  File "C:\Users\argos\Desktop\data_extract\modules\dcinside\venv\lib\site-packages\alabslib\selenium\__init__.py", line 142, in _get_browser_version
    bv = lines[-1].split()[0]
IndexError: list index out of range


2024-12-05 16:46:55,292-DCInside.log-INFO-__init__.py:485-[8820] open: get <https://www.dcinside.com/> with <1200,800>
2024-12-05 16:46:58,813-DCInside.log-INFO-__init__.py:499-[8820] closed
2024-12-05 16:48:27,274-DCInside.log-INFO-__init__.py:485-[16848] open: get <https://www.dcinside.com/> with <1200,800>
2024-12-05 16:48:33,234-DCInside.log-INFO-__init__.py:499-[16848] closed
2024-12-05 16:48:51,110-DCInside.log-INFO-__init__.py:485-[3868] open: get <https://www.dcinside.com/> with <1200,800>
2024-12-05 16:49:15,467-DCInside.log-INFO-__init__.py:485-[14104] open: get <https://www.dcinside.com/> with <1200,800>
2024-12-05 16:49:58,680-DCInside.log-INFO-__init__.py:499-[14104] closed
2024-12-05 16:50:08,494-DCInside.log-ERROR-__init__.py:475-[13108] open Error: list index out of range

2024-12-05 16:50:08,494-DCInside.log-ERROR-__init__.py:476-[13108] Traceback (most recent call last):
  File "C:\Users\argos\Desktop\data_extract\modules\dcinside\venv\lib\site-packages\alabslib\selenium\__init__.py", line 468, in __init__
    self.browser_version = self._get_browser_version()
  File "C:\Users\argos\Desktop\data_extract\modules\dcinside\venv\lib\site-packages\alabslib\selenium\__init__.py", line 142, in _get_browser_version
    bv = lines[-1].split()[0]
IndexError: list index out of range


2024-12-05 16:50:15,524-DCInside.log-INFO-__init__.py:485-[10152] open: get <https://www.dcinside.com/> with <1200,800>
2024-12-05 16:51:58,237-DCInside.log-ERROR-__init__.py:475-[6380] open Error: list index out of range

2024-12-05 16:51:58,237-DCInside.log-ERROR-__init__.py:476-[6380] Traceback (most recent call last):
  File "C:\Users\argos\Desktop\data_extract\modules\dcinside\venv\lib\site-packages\alabslib\selenium\__init__.py", line 468, in __init__
    self.browser_version = self._get_browser_version()
  File "C:\Users\argos\Desktop\data_extract\modules\dcinside\venv\lib\site-packages\alabslib\selenium\__init__.py", line 142, in _get_browser_version
    bv = lines[-1].split()[0]
IndexError: list index out of range


2024-12-05 16:52:03,845-DCInside.log-INFO-__init__.py:485-[15640] open: get <https://www.dcinside.com/> with <1200,800>
2024-12-05 16:52:09,882-DCInside.log-INFO-__init__.py:499-[15640] closed
2024-12-05 16:52:20,971-DCInside.log-INFO-__init__.py:485-[5668] open: get <https://www.dcinside.com/> with <1200,800>
2024-12-05 16:52:59,982-DCInside.log-INFO-__init__.py:485-[16464] open: get <https://www.dcinside.com/> with <1200,800>
2024-12-05 16:54:44,668-DCInside.log-INFO-__init__.py:485-[12680] open: get <https://www.dcinside.com/> with <1200,800>
2024-12-05 16:55:05,360-DCInside.log-INFO-__init__.py:485-[17208] open: get <https://www.dcinside.com/> with <1200,800>
2024-12-05 16:55:40,272-DCInside.log-ERROR-__init__.py:475-[4348] open Error: list index out of range

2024-12-05 16:55:40,272-DCInside.log-ERROR-__init__.py:476-[4348] Traceback (most recent call last):
  File "C:\Users\argos\Desktop\data_extract\modules\dcinside\venv\lib\site-packages\alabslib\selenium\__init__.py", line 468, in __init__
    self.browser_version = self._get_browser_version()
  File "C:\Users\argos\Desktop\data_extract\modules\dcinside\venv\lib\site-packages\alabslib\selenium\__init__.py", line 142, in _get_browser_version
    bv = lines[-1].split()[0]
IndexError: list index out of range


2024-12-05 16:55:45,711-DCInside.log-INFO-__init__.py:485-[16164] open: get <https://www.dcinside.com/> with <1200,800>
2024-12-05 16:56:10,088-DCInside.log-ERROR-__init__.py:475-[13504] open Error: list index out of range

2024-12-05 16:56:10,088-DCInside.log-ERROR-__init__.py:476-[13504] Traceback (most recent call last):
  File "C:\Users\argos\Desktop\data_extract\modules\dcinside\venv\lib\site-packages\alabslib\selenium\__init__.py", line 468, in __init__
    self.browser_version = self._get_browser_version()
  File "C:\Users\argos\Desktop\data_extract\modules\dcinside\venv\lib\site-packages\alabslib\selenium\__init__.py", line 142, in _get_browser_version
    bv = lines[-1].split()[0]
IndexError: list index out of range


2024-12-05 16:56:14,113-DCInside.log-ERROR-__init__.py:475-[1832] open Error: list index out of range

2024-12-05 16:56:14,113-DCInside.log-ERROR-__init__.py:476-[1832] Traceback (most recent call last):
  File "C:\Users\argos\Desktop\data_extract\modules\dcinside\venv\lib\site-packages\alabslib\selenium\__init__.py", line 468, in __init__
    self.browser_version = self._get_browser_version()
  File "C:\Users\argos\Desktop\data_extract\modules\dcinside\venv\lib\site-packages\alabslib\selenium\__init__.py", line 142, in _get_browser_version
    bv = lines[-1].split()[0]
IndexError: list index out of range


2024-12-05 16:56:19,043-DCInside.log-INFO-__init__.py:485-[7904] open: get <https://www.dcinside.com/> with <1200,800>
2024-12-05 16:56:41,152-DCInside.log-INFO-__init__.py:485-[9884] open: get <https://www.dcinside.com/> with <1200,800>
2024-12-05 16:57:09,474-DCInside.log-INFO-__init__.py:485-[15560] open: get <https://www.dcinside.com/> with <1200,800>
2024-12-05 16:57:44,600-DCInside.log-ERROR-__init__.py:475-[2684] open Error: list index out of range

2024-12-05 16:57:44,600-DCInside.log-ERROR-__init__.py:476-[2684] Traceback (most recent call last):
  File "C:\Users\argos\Desktop\data_extract\modules\dcinside\venv\lib\site-packages\alabslib\selenium\__init__.py", line 468, in __init__
    self.browser_version = self._get_browser_version()
  File "C:\Users\argos\Desktop\data_extract\modules\dcinside\venv\lib\site-packages\alabslib\selenium\__init__.py", line 142, in _get_browser_version
    bv = lines[-1].split()[0]
IndexError: list index out of range


2024-12-05 16:57:52,619-DCInside.log-INFO-__init__.py:485-[8996] open: get <https://www.dcinside.com/> with <1200,800>
2024-12-05 16:59:49,503-DCInside.log-INFO-__init__.py:485-[2884] open: get <https://www.dcinside.com/> with <1200,800>
2024-12-05 17:00:17,336-DCInside.log-INFO-__init__.py:485-[12708] open: get <https://www.dcinside.com/> with <1200,800>
2024-12-05 17:03:52,459-DCInside.log-INFO-__init__.py:485-[10476] open: get <https://www.dcinside.com/> with <1200,800>
2024-12-05 17:04:43,175-DCInside.log-INFO-__init__.py:485-[16548] open: get <https://www.dcinside.com/> with <1200,800>
2024-12-05 17:06:53,199-DCInside.log-INFO-__init__.py:485-[11496] open: get <https://www.dcinside.com/> with <1200,800>
2024-12-05 17:07:37,008-DCInside.log-INFO-__init__.py:485-[6024] open: get <https://www.dcinside.com/> with <1200,800>
2024-12-05 17:09:06,984-DCInside.log-INFO-__init__.py:485-[13024] open: get <https://www.dcinside.com/> with <1200,800>
2024-12-05 17:09:30,577-DCInside.log-INFO-__init__.py:485-[12780] open: get <https://www.dcinside.com/> with <1200,800>
2024-12-05 17:10:33,533-DCInside.log-INFO-__init__.py:485-[9684] open: get <https://www.dcinside.com/> with <1200,800>
2024-12-05 17:15:09,985-DCInside.log-INFO-__init__.py:485-[13364] open: get <https://www.dcinside.com/> with <1200,800>
2024-12-05 17:15:31,511-DCInside.log-INFO-__init__.py:499-[13364] closed
2024-12-05 17:16:07,921-DCInside.log-ERROR-__init__.py:475-[14100] open Error: list index out of range

2024-12-05 17:16:07,922-DCInside.log-ERROR-__init__.py:476-[14100] Traceback (most recent call last):
  File "C:\Users\argos\Desktop\data_extract\modules\dcinside\venv\lib\site-packages\alabslib\selenium\__init__.py", line 468, in __init__
    self.browser_version = self._get_browser_version()
  File "C:\Users\argos\Desktop\data_extract\modules\dcinside\venv\lib\site-packages\alabslib\selenium\__init__.py", line 142, in _get_browser_version
    bv = lines[-1].split()[0]
IndexError: list index out of range


2024-12-05 17:16:15,014-DCInside.log-INFO-__init__.py:485-[12800] open: get <https://www.dcinside.com/> with <1200,800>
2024-12-05 17:17:03,571-DCInside.log-INFO-__init__.py:485-[3404] open: get <https://www.dcinside.com/> with <1200,800>
2024-12-05 17:18:05,884-DCInside.log-INFO-__init__.py:485-[15504] open: get <https://www.dcinside.com/> with <1200,800>
2024-12-05 17:18:24,928-DCInside.log-INFO-__init__.py:499-[15504] closed
2024-12-05 17:20:32,927-DCInside.log-INFO-__init__.py:485-[15372] open: get <https://www.dcinside.com/> with <1200,800>
2024-12-05 17:20:46,856-DCInside.log-INFO-__init__.py:499-[15372] closed
2024-12-05 17:20:58,480-DCInside.log-INFO-__init__.py:485-[16236] open: get <https://www.dcinside.com/> with <1200,800>
2024-12-05 17:28:34,114-DCInside.log-INFO-__init__.py:485-[13348] open: get <https://www.dcinside.com/> with <1200,800>
2024-12-05 17:28:53,219-DCInside.log-INFO-__init__.py:499-[13348] closed
2024-12-05 17:34:14,921-DCInside.log-INFO-__init__.py:485-[7480] open: get <https://www.dcinside.com/> with <1200,800>
2024-12-05 17:35:35,275-DCInside.log-INFO-__init__.py:485-[6580] open: get <https://www.dcinside.com/> with <1200,800>
2024-12-05 17:36:06,228-DCInside.log-INFO-__init__.py:499-[6580] closed
2024-12-05 17:53:55,433-DCInside.log-INFO-__init__.py:485-[4472] open: get <https://www.dcinside.com/> with <1200,800>
2024-12-05 17:54:30,272-DCInside.log-INFO-__init__.py:499-[4472] closed
2024-12-05 17:54:40,007-DCInside.log-INFO-__init__.py:485-[6952] open: get <https://www.dcinside.com/> with <1200,800>
2024-12-05 17:56:11,319-DCInside.log-INFO-__init__.py:485-[10936] open: get <https://www.dcinside.com/> with <1200,800>
2024-12-05 17:56:43,851-DCInside.log-INFO-__init__.py:499-[10936] closed
2024-12-05 17:57:08,546-DCInside.log-INFO-__init__.py:485-[2840] open: get <https://www.dcinside.com/> with <1200,800>
2024-12-06 13:05:01,666-DCInside.log-INFO-__init__.py:485-[2644] open: get <https://www.dcinside.com/> with <1200,800>
2024-12-06 13:15:18,472-DCInside.log-INFO-__init__.py:485-[1240] open: get <https://www.dcinside.com/> with <1200,800>
2024-12-06 16:06:55,140-DCInside.log-INFO-__init__.py:485-[16376] open: get <https://www.dcinside.com/> with <1200,800>
2024-12-06 16:07:25,611-DCInside.log-INFO-__init__.py:485-[8832] open: get <https://www.dcinside.com/> with <1200,800>
2024-12-06 16:08:04,028-DCInside.log-INFO-__init__.py:485-[15620] open: get <https://www.dcinside.com/> with <1200,800>
2024-12-06 16:09:00,704-DCInside.log-INFO-__init__.py:485-[13272] open: get <https://www.dcinside.com/> with <1200,800>
2024-12-06 16:09:54,734-DCInside.log-INFO-__init__.py:485-[7272] open: get <https://www.dcinside.com/> with <1200,800>
2024-12-06 16:10:16,306-DCInside.log-INFO-__init__.py:485-[1792] open: get <https://www.dcinside.com/> with <1200,800>
2024-12-06 16:11:22,978-DCInside.log-INFO-__init__.py:485-[10324] open: get <https://www.dcinside.com/> with <1200,800>
2024-12-06 16:12:07,836-DCInside.log-INFO-__init__.py:485-[10216] open: get <https://www.dcinside.com/> with <1200,800>
2024-12-06 16:12:46,638-DCInside.log-INFO-__init__.py:485-[13044] open: get <https://www.dcinside.com/> with <1200,800>
2024-12-06 16:13:28,787-DCInside.log-INFO-__init__.py:485-[2488] open: get <https://www.dcinside.com/> with <1200,800>
2024-12-06 16:14:55,636-DCInside.log-INFO-__init__.py:485-[13264] open: get <https://www.dcinside.com/> with <1200,800>
2024-12-06 16:15:31,497-DCInside.log-INFO-__init__.py:485-[14516] open: get <https://www.dcinside.com/> with <1200,800>
2024-12-06 16:17:41,767-DCInside.log-INFO-__init__.py:485-[9044] open: get <https://www.dcinside.com/> with <1200,800>
2024-12-06 16:21:34,491-DCInside.log-ERROR-__init__.py:475-[292] open Error: list index out of range

2024-12-06 16:21:34,491-DCInside.log-ERROR-__init__.py:476-[292] Traceback (most recent call last):
  File "C:\Users\argos\Desktop\data_extract\modules\dcinside\venv\lib\site-packages\alabslib\selenium\__init__.py", line 468, in __init__
    self.browser_version = self._get_browser_version()
  File "C:\Users\argos\Desktop\data_extract\modules\dcinside\venv\lib\site-packages\alabslib\selenium\__init__.py", line 142, in _get_browser_version
    bv = lines[-1].split()[0]
IndexError: list index out of range


2024-12-06 16:21:39,243-DCInside.log-ERROR-__init__.py:475-[3216] open Error: list index out of range

2024-12-06 16:21:39,243-DCInside.log-ERROR-__init__.py:476-[3216] Traceback (most recent call last):
  File "C:\Users\argos\Desktop\data_extract\modules\dcinside\venv\lib\site-packages\alabslib\selenium\__init__.py", line 468, in __init__
    self.browser_version = self._get_browser_version()
  File "C:\Users\argos\Desktop\data_extract\modules\dcinside\venv\lib\site-packages\alabslib\selenium\__init__.py", line 142, in _get_browser_version
    bv = lines[-1].split()[0]
IndexError: list index out of range


2024-12-06 16:29:57,918-DCInside.log-INFO-__init__.py:485-[15604] open: get <https://www.dcinside.com/> with <1200,800>
2024-12-06 16:29:59,038-DCInside.log-INFO-__init__.py:499-[15604] closed
2024-12-06 16:31:59,265-DCInside.log-INFO-__init__.py:485-[8012] open: get <https://www.dcinside.com/> with <1200,800>
2024-12-06 16:32:00,630-DCInside.log-ERROR-__init__.py:475-[3080] open Error: list index out of range

2024-12-06 16:32:00,631-DCInside.log-ERROR-__init__.py:476-[3080] Traceback (most recent call last):
  File "C:\Users\argos\Desktop\data_extract\modules\dcinside\venv\lib\site-packages\alabslib\selenium\__init__.py", line 468, in __init__
    self.browser_version = self._get_browser_version()
  File "C:\Users\argos\Desktop\data_extract\modules\dcinside\venv\lib\site-packages\alabslib\selenium\__init__.py", line 142, in _get_browser_version
    bv = lines[-1].split()[0]
IndexError: list index out of range


2024-12-06 16:32:00,706-DCInside.log-INFO-__init__.py:499-[8012] closed
2024-12-06 16:32:16,233-DCInside.log-INFO-__init__.py:485-[4428] open: get <https://www.dcinside.com/> with <1200,800>
2024-12-06 16:36:15,641-DCInside.log-INFO-__init__.py:485-[16948] open: get <https://www.dcinside.com/> with <1200,800>
2024-12-06 16:59:10,108-DCInside.log-INFO-__init__.py:485-[3760] open: get <https://www.dcinside.com/> with <1200,800>
2024-12-06 16:59:31,202-DCInside.log-ERROR-__init__.py:504-[3760] close Error: Message: disconnected: not connected to DevTools
  (failed to check if window was closed: disconnected: not connected to DevTools)
  (Session info: chrome=131.0.6778.109)


2024-12-06 16:59:31,202-DCInside.log-ERROR-__init__.py:505-[3760] Traceback (most recent call last):
  File "C:\Users\argos\Desktop\data_extract\modules\dcinside\venv\lib\site-packages\alabslib\selenium\__init__.py", line 498, in close
    self.driver.close()
  File "C:\Users\argos\Desktop\data_extract\modules\dcinside\venv\lib\site-packages\selenium\webdriver\remote\webdriver.py", line 688, in close
    self.execute(Command.CLOSE)
  File "C:\Users\argos\Desktop\data_extract\modules\dcinside\venv\lib\site-packages\selenium\webdriver\remote\webdriver.py", line 321, in execute
    self.error_handler.check_response(response)
  File "C:\Users\argos\Desktop\data_extract\modules\dcinside\venv\lib\site-packages\selenium\webdriver\remote\errorhandler.py", line 242, in check_response
    raise exception_class(message, screen, stacktrace)
selenium.common.exceptions.WebDriverException: Message: disconnected: not connected to DevTools
  (failed to check if window was closed: disconnected: not connected to DevTools)
  (Session info: chrome=131.0.6778.109)



2024-12-06 17:00:46,601-DCInside.log-INFO-__init__.py:485-[12536] open: get <https://www.dcinside.com/> with <1200,800>
2024-12-06 17:01:49,122-DCInside.log-INFO-__init__.py:485-[5048] open: get <https://www.dcinside.com/> with <1200,800>
2024-12-06 17:03:34,411-DCInside.log-INFO-__init__.py:485-[10600] open: get <https://www.dcinside.com/> with <1200,800>
2024-12-06 17:04:07,637-DCInside.log-INFO-__init__.py:485-[14756] open: get <https://www.dcinside.com/> with <1200,800>
2024-12-06 17:04:41,547-DCInside.log-INFO-__init__.py:485-[16056] open: get <https://www.dcinside.com/> with <1200,800>
2024-12-06 17:05:43,977-DCInside.log-ERROR-__init__.py:475-[10608] open Error: list index out of range

2024-12-06 17:05:43,977-DCInside.log-ERROR-__init__.py:476-[10608] Traceback (most recent call last):
  File "C:\Users\argos\Desktop\data_extract\modules\dcinside\venv\lib\site-packages\alabslib\selenium\__init__.py", line 468, in __init__
    self.browser_version = self._get_browser_version()
  File "C:\Users\argos\Desktop\data_extract\modules\dcinside\venv\lib\site-packages\alabslib\selenium\__init__.py", line 142, in _get_browser_version
    bv = lines[-1].split()[0]
IndexError: list index out of range


2024-12-06 17:05:52,297-DCInside.log-INFO-__init__.py:485-[116] open: get <https://www.dcinside.com/> with <1200,800>
2024-12-06 17:07:34,643-DCInside.log-INFO-__init__.py:485-[1196] open: get <https://www.dcinside.com/> with <1200,800>
2024-12-06 17:08:09,327-DCInside.log-INFO-__init__.py:499-[1196] closed
2024-12-06 17:08:30,621-DCInside.log-INFO-__init__.py:485-[14144] open: get <https://www.dcinside.com/> with <1200,800>
2024-12-06 17:09:54,640-DCInside.log-ERROR-__init__.py:504-[14144] close Error: Message: disconnected: not connected to DevTools
  (failed to check if window was closed: disconnected: not connected to DevTools)
  (Session info: chrome=131.0.6778.109)


2024-12-06 17:09:54,640-DCInside.log-ERROR-__init__.py:505-[14144] Traceback (most recent call last):
  File "C:\Users\argos\Desktop\data_extract\modules\dcinside\venv\lib\site-packages\alabslib\selenium\__init__.py", line 498, in close
    self.driver.close()
  File "C:\Users\argos\Desktop\data_extract\modules\dcinside\venv\lib\site-packages\selenium\webdriver\remote\webdriver.py", line 688, in close
    self.execute(Command.CLOSE)
  File "C:\Users\argos\Desktop\data_extract\modules\dcinside\venv\lib\site-packages\selenium\webdriver\remote\webdriver.py", line 321, in execute
    self.error_handler.check_response(response)
  File "C:\Users\argos\Desktop\data_extract\modules\dcinside\venv\lib\site-packages\selenium\webdriver\remote\errorhandler.py", line 242, in check_response
    raise exception_class(message, screen, stacktrace)
selenium.common.exceptions.WebDriverException: Message: disconnected: not connected to DevTools
  (failed to check if window was closed: disconnected: not connected to DevTools)
  (Session info: chrome=131.0.6778.109)



2024-12-06 17:09:59,943-DCInside.log-INFO-__init__.py:485-[5888] open: get <https://www.dcinside.com/> with <1200,800>
2024-12-06 17:11:09,220-DCInside.log-INFO-__init__.py:485-[17152] open: get <https://www.dcinside.com/> with <1200,800>
2024-12-06 17:12:19,261-DCInside.log-INFO-__init__.py:485-[4840] open: get <https://www.dcinside.com/> with <1200,800>
2024-12-06 17:13:00,073-DCInside.log-INFO-__init__.py:485-[10808] open: get <https://www.dcinside.com/> with <1200,800>
2024-12-06 17:13:37,851-DCInside.log-INFO-__init__.py:485-[17148] open: get <https://www.dcinside.com/> with <1200,800>
2024-12-06 17:14:28,752-DCInside.log-INFO-__init__.py:499-[17148] closed
2024-12-06 17:15:55,985-DCInside.log-INFO-__init__.py:485-[6884] open: get <https://www.dcinside.com/> with <1200,800>
2024-12-06 17:16:52,812-DCInside.log-INFO-__init__.py:499-[6884] closed
2024-12-06 17:18:48,285-DCInside.log-INFO-__init__.py:485-[5864] open: get <https://www.dcinside.com/> with <1200,800>
2024-12-06 17:19:23,497-DCInside.log-INFO-__init__.py:499-[5864] closed
2024-12-06 17:22:27,412-DCInside.log-INFO-__init__.py:485-[5176] open: get <https://search.dcinside.com/post> with <1200,800>
2024-12-06 17:22:39,096-DCInside.log-INFO-__init__.py:499-[5176] closed
2024-12-06 17:23:51,381-DCInside.log-INFO-__init__.py:485-[9956] open: get <https://search.dcinside.com/post> with <1200,800>
2024-12-06 17:24:03,115-DCInside.log-INFO-__init__.py:499-[9956] closed
2024-12-06 17:25:08,795-DCInside.log-ERROR-__init__.py:475-[11812] open Error: list index out of range

2024-12-06 17:25:08,795-DCInside.log-ERROR-__init__.py:476-[11812] Traceback (most recent call last):
  File "C:\Users\argos\Desktop\data_extract\modules\dcinside\venv\lib\site-packages\alabslib\selenium\__init__.py", line 468, in __init__
    self.browser_version = self._get_browser_version()
  File "C:\Users\argos\Desktop\data_extract\modules\dcinside\venv\lib\site-packages\alabslib\selenium\__init__.py", line 142, in _get_browser_version
    bv = lines[-1].split()[0]
IndexError: list index out of range


2024-12-06 17:25:13,423-DCInside.log-INFO-__init__.py:485-[11088] open: get <https://search.dcinside.com/post> with <1200,800>
2024-12-06 17:25:25,115-DCInside.log-INFO-__init__.py:499-[11088] closed
2024-12-06 17:26:51,736-DCInside.log-INFO-__init__.py:485-[12500] open: get <https://search.dcinside.com/post> with <1200,800>
2024-12-06 17:27:03,533-DCInside.log-INFO-__init__.py:499-[12500] closed
2024-12-06 17:27:55,028-DCInside.log-INFO-__init__.py:485-[7192] open: get <https://search.dcinside.com/post> with <1200,800>
2024-12-06 17:29:08,952-DCInside.log-INFO-__init__.py:485-[13172] open: get <https://search.dcinside.com/post> with <1200,800>
2024-12-06 17:30:15,038-DCInside.log-ERROR-__init__.py:475-[8504] open Error: list index out of range

2024-12-06 17:30:15,038-DCInside.log-ERROR-__init__.py:476-[8504] Traceback (most recent call last):
  File "C:\Users\argos\Desktop\data_extract\modules\dcinside\venv\lib\site-packages\alabslib\selenium\__init__.py", line 468, in __init__
    self.browser_version = self._get_browser_version()
  File "C:\Users\argos\Desktop\data_extract\modules\dcinside\venv\lib\site-packages\alabslib\selenium\__init__.py", line 142, in _get_browser_version
    bv = lines[-1].split()[0]
IndexError: list index out of range


2024-12-06 17:30:20,986-DCInside.log-INFO-__init__.py:485-[8936] open: get <https://search.dcinside.com/post> with <1200,800>
2024-12-06 17:30:57,228-DCInside.log-INFO-__init__.py:485-[15784] open: get <https://search.dcinside.com/post> with <1200,800>
2024-12-06 17:31:04,887-DCInside.log-INFO-__init__.py:485-[820] open: get <https://search.dcinside.com/post> with <1200,800>
2024-12-06 17:31:27,188-DCInside.log-ERROR-__init__.py:504-[820] close Error: Message: no such window: target window already closed
from unknown error: web view not found
  (Session info: chrome=131.0.6778.109)


2024-12-06 17:31:27,188-DCInside.log-ERROR-__init__.py:505-[820] Traceback (most recent call last):
  File "C:\Users\argos\Desktop\data_extract\modules\dcinside\venv\lib\site-packages\alabslib\selenium\__init__.py", line 498, in close
    self.driver.close()
  File "C:\Users\argos\Desktop\data_extract\modules\dcinside\venv\lib\site-packages\selenium\webdriver\remote\webdriver.py", line 688, in close
    self.execute(Command.CLOSE)
  File "C:\Users\argos\Desktop\data_extract\modules\dcinside\venv\lib\site-packages\selenium\webdriver\remote\webdriver.py", line 321, in execute
    self.error_handler.check_response(response)
  File "C:\Users\argos\Desktop\data_extract\modules\dcinside\venv\lib\site-packages\selenium\webdriver\remote\errorhandler.py", line 242, in check_response
    raise exception_class(message, screen, stacktrace)
selenium.common.exceptions.NoSuchWindowException: Message: no such window: target window already closed
from unknown error: web view not found
  (Session info: chrome=131.0.6778.109)



2024-12-06 17:32:56,430-DCInside.log-INFO-__init__.py:485-[13348] open: get <https://search.dcinside.com/post> with <1200,800>
2024-12-06 17:33:16,551-DCInside.log-INFO-__init__.py:499-[13348] closed
2024-12-06 17:34:14,990-DCInside.log-INFO-__init__.py:485-[8300] open: get <https://search.dcinside.com/post> with <1200,800>
2024-12-06 17:34:52,036-DCInside.log-INFO-__init__.py:485-[10612] open: get <https://search.dcinside.com/post> with <1200,800>
2024-12-06 17:36:03,132-DCInside.log-INFO-__init__.py:485-[3352] open: get <https://search.dcinside.com/post> with <1200,800>
2024-12-06 17:36:42,620-DCInside.log-INFO-__init__.py:485-[11768] open: get <https://search.dcinside.com/post> with <1200,800>
2024-12-06 17:38:01,312-DCInside.log-INFO-__init__.py:485-[5040] open: get <https://search.dcinside.com/post> with <1200,800>
2024-12-06 17:38:12,973-DCInside.log-INFO-__init__.py:499-[5040] closed
2024-12-06 17:40:59,543-DCInside.log-INFO-__init__.py:485-[15396] open: get <https://search.dcinside.com/post> with <1200,800>
2024-12-06 17:41:11,260-DCInside.log-INFO-__init__.py:499-[15396] closed
2024-12-06 17:41:16,298-DCInside.log-ERROR-__init__.py:475-[8204] open Error: list index out of range

2024-12-06 17:41:16,299-DCInside.log-ERROR-__init__.py:476-[8204] Traceback (most recent call last):
  File "C:\Users\argos\Desktop\data_extract\modules\dcinside\venv\lib\site-packages\alabslib\selenium\__init__.py", line 468, in __init__
    self.browser_version = self._get_browser_version()
  File "C:\Users\argos\Desktop\data_extract\modules\dcinside\venv\lib\site-packages\alabslib\selenium\__init__.py", line 142, in _get_browser_version
    bv = lines[-1].split()[0]
IndexError: list index out of range


2024-12-06 17:44:06,053-DCInside.log-INFO-__init__.py:485-[11964] open: get <https://search.dcinside.com/post> with <1200,800>
2024-12-06 17:45:00,453-DCInside.log-INFO-__init__.py:485-[7944] open: get <https://search.dcinside.com/post> with <1200,800>
2024-12-06 17:45:12,099-DCInside.log-INFO-__init__.py:499-[7944] closed
